2019-04-11 20:49:33.7504|ERROR|Chatison.Areas.Admin.Controllers.ContactController|System.Data.Entity.Infrastructure.DbUpdateException: An error occurred while updating the entries. See the inner exception for details. ---> System.Data.Entity.Core.UpdateException: An error occurred while updating the entries. See the inner exception for details. ---> MySql.Data.MySqlClient.MySqlException: Column 'UserId' cannot be null
   at MySql.Data.MySqlClient.MySqlStream.ReadPacket()
   at MySql.Data.MySqlClient.NativeDriver.GetResult(Int32& affectedRow, Int64& insertedId)
   at MySql.Data.MySqlClient.Driver.GetResult(Int32 statementId, Int32& affectedRows, Int64& insertedId)
   at MySql.Data.MySqlClient.Driver.NextResult(Int32 statementId, Boolean force)
   at MySql.Data.MySqlClient.MySqlDataReader.NextResult()
   at MySql.Data.MySqlClient.MySqlCommand.ExecuteReader(CommandBehavior behavior)
   at MySql.Data.MySqlClient.MySqlCommand.ExecuteNonQuery()
   at MySql.Data.Entity.EFMySqlCommand.ExecuteNonQuery()
   at System.Data.Common.DbCommand.ExecuteNonQueryAsync(CancellationToken cancellationToken)
--- End of stack trace from previous location where exception was thrown ---
   at System.Runtime.CompilerServices.TaskAwaiter.ThrowForNonSuccess(Task task)
   at System.Runtime.CompilerServices.TaskAwaiter.HandleNonSuccessAndDebuggerNotification(Task task)
   at System.Data.Entity.Utilities.TaskExtensions.CultureAwaiter`1.GetResult()
   at System.Data.Entity.Core.Mapping.Update.Internal.DynamicUpdateCommand.<ExecuteAsync>d__0.MoveNext()
--- End of stack trace from previous location where exception was thrown ---
   at System.Runtime.CompilerServices.TaskAwaiter.ThrowForNonSuccess(Task task)
   at System.Runtime.CompilerServices.TaskAwaiter.HandleNonSuccessAndDebuggerNotification(Task task)
   at System.Data.Entity.Core.Mapping.Update.Internal.UpdateTranslator.<UpdateAsync>d__0.MoveNext()
   --- End of inner exception stack trace ---
   at System.Data.Entity.Core.Mapping.Update.Internal.UpdateTranslator.<UpdateAsync>d__0.MoveNext()
--- End of stack trace from previous location where exception was thrown ---
   at System.Runtime.CompilerServices.TaskAwaiter.ThrowForNonSuccess(Task task)
   at System.Runtime.CompilerServices.TaskAwaiter.HandleNonSuccessAndDebuggerNotification(Task task)
   at System.Data.Entity.Core.Objects.ObjectContext.<ExecuteInTransactionAsync>d__3d`1.MoveNext()
--- End of stack trace from previous location where exception was thrown ---
   at System.Runtime.CompilerServices.TaskAwaiter.ThrowForNonSuccess(Task task)
   at System.Runtime.CompilerServices.TaskAwaiter.HandleNonSuccessAndDebuggerNotification(Task task)
   at System.Data.Entity.Core.Objects.ObjectContext.<SaveChangesToStoreAsync>d__39.MoveNext()
--- End of stack trace from previous location where exception was thrown ---
   at System.Runtime.CompilerServices.TaskAwaiter.ThrowForNonSuccess(Task task)
   at System.Runtime.CompilerServices.TaskAwaiter.HandleNonSuccessAndDebuggerNotification(Task task)
   at System.Data.Entity.Core.Objects.ObjectContext.<SaveChangesInternalAsync>d__31.MoveNext()
   --- End of inner exception stack trace ---
   at System.Runtime.CompilerServices.TaskAwaiter.ThrowForNonSuccess(Task task)
   at System.Runtime.CompilerServices.TaskAwaiter.HandleNonSuccessAndDebuggerNotification(Task task)
   at System.Runtime.CompilerServices.TaskAwaiter`1.GetResult()
   at Chatison.DataLayer.UnitOfWork.<SaveChangesAsync>d__5.MoveNext() in E:\Projects\Client\Chatison\Chatison.DataLayer\UnitOfWork.cs:line 29
--- End of stack trace from previous location where exception was thrown ---
   at System.Runtime.CompilerServices.TaskAwaiter.ThrowForNonSuccess(Task task)
   at System.Runtime.CompilerServices.TaskAwaiter.HandleNonSuccessAndDebuggerNotification(Task task)
   at System.Runtime.CompilerServices.TaskAwaiter`1.GetResult()
   at Chatison.Managers.ContactManager.<EditAsync>d__7.MoveNext() in E:\Projects\Client\Chatison\Chatison.Managers\ContactManager.cs:line 62
--- End of stack trace from previous location where exception was thrown ---
   at System.Runtime.CompilerServices.TaskAwaiter.ThrowForNonSuccess(Task task)
   at System.Runtime.CompilerServices.TaskAwaiter.HandleNonSuccessAndDebuggerNotification(Task task)
   at System.Runtime.CompilerServices.TaskAwaiter.GetResult()
   at Chatison.Areas.Admin.Controllers.ContactController.<Edit>d__11.MoveNext() in E:\Projects\Client\Chatison\Chatison\Areas\Admin\Controllers\ContactController.cs:line 128
2019-04-11 21:16:15.2090|ERROR|Chatison.Areas.Admin.Controllers.ContactController|System.InvalidOperationException: Sequence contains no matching element
   at System.Linq.Enumerable.Single[TSource](IEnumerable`1 source, Func`2 predicate)
   at Chatison.Factory.ContactFactory.CreateContact(Contact contact, EditContactVm model) in E:\Projects\Client\Chatison\Chatison.Factory\ContactFactory.cs:line 68
   at Chatison.Managers.ContactManager.<EditAsync>d__7.MoveNext() in E:\Projects\Client\Chatison\Chatison.Managers\ContactManager.cs:line 60
--- End of stack trace from previous location where exception was thrown ---
   at System.Runtime.CompilerServices.TaskAwaiter.ThrowForNonSuccess(Task task)
   at System.Runtime.CompilerServices.TaskAwaiter.HandleNonSuccessAndDebuggerNotification(Task task)
   at System.Runtime.CompilerServices.TaskAwaiter.GetResult()
   at Chatison.Areas.Admin.Controllers.ContactController.<Edit>d__11.MoveNext() in E:\Projects\Client\Chatison\Chatison\Areas\Admin\Controllers\ContactController.cs:line 128
2019-04-11 21:20:03.5927|ERROR|Chatison.Areas.Admin.Controllers.ContactController|System.Data.Entity.Infrastructure.DbUpdateException: An error occurred while updating the entries. See the inner exception for details. ---> System.Data.Entity.Core.UpdateException: An error occurred while updating the entries. See the inner exception for details. ---> MySql.Data.MySqlClient.MySqlException: Column 'UserId' cannot be null
   at MySql.Data.MySqlClient.MySqlStream.ReadPacket()
   at MySql.Data.MySqlClient.NativeDriver.GetResult(Int32& affectedRow, Int64& insertedId)
   at MySql.Data.MySqlClient.Driver.GetResult(Int32 statementId, Int32& affectedRows, Int64& insertedId)
   at MySql.Data.MySqlClient.Driver.NextResult(Int32 statementId, Boolean force)
   at MySql.Data.MySqlClient.MySqlDataReader.NextResult()
   at MySql.Data.MySqlClient.MySqlCommand.ExecuteReader(CommandBehavior behavior)
   at MySql.Data.MySqlClient.MySqlCommand.ExecuteNonQuery()
   at MySql.Data.Entity.EFMySqlCommand.ExecuteNonQuery()
   at System.Data.Common.DbCommand.ExecuteNonQueryAsync(CancellationToken cancellationToken)
--- End of stack trace from previous location where exception was thrown ---
   at System.Runtime.CompilerServices.TaskAwaiter.ThrowForNonSuccess(Task task)
   at System.Runtime.CompilerServices.TaskAwaiter.HandleNonSuccessAndDebuggerNotification(Task task)
   at System.Data.Entity.Utilities.TaskExtensions.CultureAwaiter`1.GetResult()
   at System.Data.Entity.Core.Mapping.Update.Internal.DynamicUpdateCommand.<ExecuteAsync>d__0.MoveNext()
--- End of stack trace from previous location where exception was thrown ---
   at System.Runtime.CompilerServices.TaskAwaiter.ThrowForNonSuccess(Task task)
   at System.Runtime.CompilerServices.TaskAwaiter.HandleNonSuccessAndDebuggerNotification(Task task)
   at System.Data.Entity.Core.Mapping.Update.Internal.UpdateTranslator.<UpdateAsync>d__0.MoveNext()
   --- End of inner exception stack trace ---
   at System.Data.Entity.Core.Mapping.Update.Internal.UpdateTranslator.<UpdateAsync>d__0.MoveNext()
--- End of stack trace from previous location where exception was thrown ---
   at System.Runtime.CompilerServices.TaskAwaiter.ThrowForNonSuccess(Task task)
   at System.Runtime.CompilerServices.TaskAwaiter.HandleNonSuccessAndDebuggerNotification(Task task)
   at System.Data.Entity.Core.Objects.ObjectContext.<ExecuteInTransactionAsync>d__3d`1.MoveNext()
--- End of stack trace from previous location where exception was thrown ---
   at System.Runtime.CompilerServices.TaskAwaiter.ThrowForNonSuccess(Task task)
   at System.Runtime.CompilerServices.TaskAwaiter.HandleNonSuccessAndDebuggerNotification(Task task)
   at System.Data.Entity.Core.Objects.ObjectContext.<SaveChangesToStoreAsync>d__39.MoveNext()
--- End of stack trace from previous location where exception was thrown ---
   at System.Runtime.CompilerServices.TaskAwaiter.ThrowForNonSuccess(Task task)
   at System.Runtime.CompilerServices.TaskAwaiter.HandleNonSuccessAndDebuggerNotification(Task task)
   at System.Data.Entity.Core.Objects.ObjectContext.<SaveChangesInternalAsync>d__31.MoveNext()
   --- End of inner exception stack trace ---
   at System.Runtime.CompilerServices.TaskAwaiter.ThrowForNonSuccess(Task task)
   at System.Runtime.CompilerServices.TaskAwaiter.HandleNonSuccessAndDebuggerNotification(Task task)
   at System.Runtime.CompilerServices.TaskAwaiter`1.GetResult()
   at Chatison.DataLayer.UnitOfWork.<SaveChangesAsync>d__5.MoveNext() in E:\Projects\Client\Chatison\Chatison.DataLayer\UnitOfWork.cs:line 29
--- End of stack trace from previous location where exception was thrown ---
   at System.Runtime.CompilerServices.TaskAwaiter.ThrowForNonSuccess(Task task)
   at System.Runtime.CompilerServices.TaskAwaiter.HandleNonSuccessAndDebuggerNotification(Task task)
   at System.Runtime.CompilerServices.TaskAwaiter`1.GetResult()
   at Chatison.Managers.ContactManager.<EditAsync>d__7.MoveNext() in E:\Projects\Client\Chatison\Chatison.Managers\ContactManager.cs:line 64
--- End of stack trace from previous location where exception was thrown ---
   at System.Runtime.CompilerServices.TaskAwaiter.ThrowForNonSuccess(Task task)
   at System.Runtime.CompilerServices.TaskAwaiter.HandleNonSuccessAndDebuggerNotification(Task task)
   at System.Runtime.CompilerServices.TaskAwaiter.GetResult()
   at Chatison.Areas.Admin.Controllers.ContactController.<Edit>d__11.MoveNext() in E:\Projects\Client\Chatison\Chatison\Areas\Admin\Controllers\ContactController.cs:line 128
2019-04-11 21:45:07.3493|ERROR|Chatison.Areas.Admin.Controllers.ContactController|System.Data.Entity.Infrastructure.DbUpdateException: An error occurred while updating the entries. See the inner exception for details. ---> System.Data.Entity.Core.UpdateException: An error occurred while updating the entries. See the inner exception for details. ---> MySql.Data.MySqlClient.MySqlException: Column 'UserId' cannot be null
   at MySql.Data.MySqlClient.MySqlStream.ReadPacket()
   at MySql.Data.MySqlClient.NativeDriver.GetResult(Int32& affectedRow, Int64& insertedId)
   at MySql.Data.MySqlClient.Driver.GetResult(Int32 statementId, Int32& affectedRows, Int64& insertedId)
   at MySql.Data.MySqlClient.Driver.NextResult(Int32 statementId, Boolean force)
   at MySql.Data.MySqlClient.MySqlDataReader.NextResult()
   at MySql.Data.MySqlClient.MySqlCommand.ExecuteReader(CommandBehavior behavior)
   at MySql.Data.MySqlClient.MySqlCommand.ExecuteNonQuery()
   at MySql.Data.Entity.EFMySqlCommand.ExecuteNonQuery()
   at System.Data.Common.DbCommand.ExecuteNonQueryAsync(CancellationToken cancellationToken)
--- End of stack trace from previous location where exception was thrown ---
   at System.Runtime.CompilerServices.TaskAwaiter.ThrowForNonSuccess(Task task)
   at System.Runtime.CompilerServices.TaskAwaiter.HandleNonSuccessAndDebuggerNotification(Task task)
   at System.Data.Entity.Utilities.TaskExtensions.CultureAwaiter`1.GetResult()
   at System.Data.Entity.Core.Mapping.Update.Internal.DynamicUpdateCommand.<ExecuteAsync>d__0.MoveNext()
--- End of stack trace from previous location where exception was thrown ---
   at System.Runtime.CompilerServices.TaskAwaiter.ThrowForNonSuccess(Task task)
   at System.Runtime.CompilerServices.TaskAwaiter.HandleNonSuccessAndDebuggerNotification(Task task)
   at System.Data.Entity.Core.Mapping.Update.Internal.UpdateTranslator.<UpdateAsync>d__0.MoveNext()
   --- End of inner exception stack trace ---
   at System.Data.Entity.Core.Mapping.Update.Internal.UpdateTranslator.<UpdateAsync>d__0.MoveNext()
--- End of stack trace from previous location where exception was thrown ---
   at System.Runtime.CompilerServices.TaskAwaiter.ThrowForNonSuccess(Task task)
   at System.Runtime.CompilerServices.TaskAwaiter.HandleNonSuccessAndDebuggerNotification(Task task)
   at System.Data.Entity.Core.Objects.ObjectContext.<ExecuteInTransactionAsync>d__3d`1.MoveNext()
--- End of stack trace from previous location where exception was thrown ---
   at System.Runtime.CompilerServices.TaskAwaiter.ThrowForNonSuccess(Task task)
   at System.Runtime.CompilerServices.TaskAwaiter.HandleNonSuccessAndDebuggerNotification(Task task)
   at System.Data.Entity.Core.Objects.ObjectContext.<SaveChangesToStoreAsync>d__39.MoveNext()
--- End of stack trace from previous location where exception was thrown ---
   at System.Runtime.CompilerServices.TaskAwaiter.ThrowForNonSuccess(Task task)
   at System.Runtime.CompilerServices.TaskAwaiter.HandleNonSuccessAndDebuggerNotification(Task task)
   at System.Data.Entity.Core.Objects.ObjectContext.<SaveChangesInternalAsync>d__31.MoveNext()
   --- End of inner exception stack trace ---
   at System.Runtime.CompilerServices.TaskAwaiter.ThrowForNonSuccess(Task task)
   at System.Runtime.CompilerServices.TaskAwaiter.HandleNonSuccessAndDebuggerNotification(Task task)
   at System.Runtime.CompilerServices.TaskAwaiter`1.GetResult()
   at Chatison.DataLayer.UnitOfWork.<SaveChangesAsync>d__5.MoveNext() in E:\Projects\Client\Chatison\Chatison.DataLayer\UnitOfWork.cs:line 29
--- End of stack trace from previous location where exception was thrown ---
   at System.Runtime.CompilerServices.TaskAwaiter.ThrowForNonSuccess(Task task)
   at System.Runtime.CompilerServices.TaskAwaiter.HandleNonSuccessAndDebuggerNotification(Task task)
   at System.Runtime.CompilerServices.TaskAwaiter`1.GetResult()
   at Chatison.Managers.ContactManager.<EditAsync>d__7.MoveNext() in E:\Projects\Client\Chatison\Chatison.Managers\ContactManager.cs:line 62
--- End of stack trace from previous location where exception was thrown ---
   at System.Runtime.CompilerServices.TaskAwaiter.ThrowForNonSuccess(Task task)
   at System.Runtime.CompilerServices.TaskAwaiter.HandleNonSuccessAndDebuggerNotification(Task task)
   at System.Runtime.CompilerServices.TaskAwaiter.GetResult()
   at Chatison.Areas.Admin.Controllers.ContactController.<Edit>d__11.MoveNext() in E:\Projects\Client\Chatison\Chatison\Areas\Admin\Controllers\ContactController.cs:line 128
2019-04-11 21:49:28.2013|ERROR|Chatison.Areas.Admin.Controllers.ContactController|System.Data.Entity.Infrastructure.DbUpdateException: An error occurred while updating the entries. See the inner exception for details. ---> System.Data.Entity.Core.UpdateException: An error occurred while updating the entries. See the inner exception for details. ---> MySql.Data.MySqlClient.MySqlException: Cannot add or update a child row: a foreign key constraint fails ("chatison"."groupcontacts", CONSTRAINT "FK_GroupContacts_Contacts_UserId" FOREIGN KEY ("UserId") REFERENCES "contacts" ("UserId") ON DELETE CASCADE ON UPDATE CASCADE)
   at MySql.Data.MySqlClient.MySqlStream.ReadPacket()
   at MySql.Data.MySqlClient.NativeDriver.GetResult(Int32& affectedRow, Int64& insertedId)
   at MySql.Data.MySqlClient.Driver.GetResult(Int32 statementId, Int32& affectedRows, Int64& insertedId)
   at MySql.Data.MySqlClient.Driver.NextResult(Int32 statementId, Boolean force)
   at MySql.Data.MySqlClient.MySqlDataReader.NextResult()
   at MySql.Data.MySqlClient.MySqlCommand.ExecuteReader(CommandBehavior behavior)
   at MySql.Data.MySqlClient.MySqlCommand.ExecuteNonQuery()
   at MySql.Data.Entity.EFMySqlCommand.ExecuteNonQuery()
   at System.Data.Common.DbCommand.ExecuteNonQueryAsync(CancellationToken cancellationToken)
--- End of stack trace from previous location where exception was thrown ---
   at System.Runtime.CompilerServices.TaskAwaiter.ThrowForNonSuccess(Task task)
   at System.Runtime.CompilerServices.TaskAwaiter.HandleNonSuccessAndDebuggerNotification(Task task)
   at System.Data.Entity.Utilities.TaskExtensions.CultureAwaiter`1.GetResult()
   at System.Data.Entity.Core.Mapping.Update.Internal.DynamicUpdateCommand.<ExecuteAsync>d__0.MoveNext()
--- End of stack trace from previous location where exception was thrown ---
   at System.Runtime.CompilerServices.TaskAwaiter.ThrowForNonSuccess(Task task)
   at System.Runtime.CompilerServices.TaskAwaiter.HandleNonSuccessAndDebuggerNotification(Task task)
   at System.Data.Entity.Core.Mapping.Update.Internal.UpdateTranslator.<UpdateAsync>d__0.MoveNext()
   --- End of inner exception stack trace ---
   at System.Data.Entity.Core.Mapping.Update.Internal.UpdateTranslator.<UpdateAsync>d__0.MoveNext()
--- End of stack trace from previous location where exception was thrown ---
   at System.Runtime.CompilerServices.TaskAwaiter.ThrowForNonSuccess(Task task)
   at System.Runtime.CompilerServices.TaskAwaiter.HandleNonSuccessAndDebuggerNotification(Task task)
   at System.Data.Entity.Core.Objects.ObjectContext.<ExecuteInTransactionAsync>d__3d`1.MoveNext()
--- End of stack trace from previous location where exception was thrown ---
   at System.Runtime.CompilerServices.TaskAwaiter.ThrowForNonSuccess(Task task)
   at System.Runtime.CompilerServices.TaskAwaiter.HandleNonSuccessAndDebuggerNotification(Task task)
   at System.Data.Entity.Core.Objects.ObjectContext.<SaveChangesToStoreAsync>d__39.MoveNext()
--- End of stack trace from previous location where exception was thrown ---
   at System.Runtime.CompilerServices.TaskAwaiter.ThrowForNonSuccess(Task task)
   at System.Runtime.CompilerServices.TaskAwaiter.HandleNonSuccessAndDebuggerNotification(Task task)
   at System.Data.Entity.Core.Objects.ObjectContext.<SaveChangesInternalAsync>d__31.MoveNext()
   --- End of inner exception stack trace ---
   at System.Runtime.CompilerServices.TaskAwaiter.ThrowForNonSuccess(Task task)
   at System.Runtime.CompilerServices.TaskAwaiter.HandleNonSuccessAndDebuggerNotification(Task task)
   at System.Runtime.CompilerServices.TaskAwaiter`1.GetResult()
   at Chatison.DataLayer.UnitOfWork.<SaveChangesAsync>d__5.MoveNext() in E:\Projects\Client\Chatison\Chatison.DataLayer\UnitOfWork.cs:line 29
--- End of stack trace from previous location where exception was thrown ---
   at System.Runtime.CompilerServices.TaskAwaiter.ThrowForNonSuccess(Task task)
   at System.Runtime.CompilerServices.TaskAwaiter.HandleNonSuccessAndDebuggerNotification(Task task)
   at System.Runtime.CompilerServices.TaskAwaiter`1.GetResult()
   at Chatison.Managers.ContactManager.<EditAsync>d__7.MoveNext() in E:\Projects\Client\Chatison\Chatison.Managers\ContactManager.cs:line 62
--- End of stack trace from previous location where exception was thrown ---
   at System.Runtime.CompilerServices.TaskAwaiter.ThrowForNonSuccess(Task task)
   at System.Runtime.CompilerServices.TaskAwaiter.HandleNonSuccessAndDebuggerNotification(Task task)
   at System.Runtime.CompilerServices.TaskAwaiter.GetResult()
   at Chatison.Areas.Admin.Controllers.ContactController.<Edit>d__11.MoveNext() in E:\Projects\Client\Chatison\Chatison\Areas\Admin\Controllers\ContactController.cs:line 128
